Workbook

Sheet Read Me
A1: The Fourth Estate (variant) -- card content
A2: Exported from docs/deck-dc.csv, docs/elections-dc.csv and docs/papers-dc.csv on the variant branch.
A3: Those CSV files are what the game reads; this workbook is a copy. Influence and prestige are split into readable columns here;
A4: every other column keeps its CSV name, and the key column identifies each card, so edited rows can be imported back.
A6: Sheets
A7: Stories -- every card kind: stories, media events, starters (Letter, Local Notice), Editorial, Scandal.
A8: Elections -- the 17 election cards: two candidates each, thresholds, the card's power and its First Appearance event.
A9: Newspapers -- the eight papers (DC's Super Heroes) and their abilities.
A10: Summary -- counts by type, theme and era, as formulas over the Stories sheet.
A12: Stories columns
A13: cost = price on the exchange; Prestige = the score; Influence (plain) = spends on anything;
A14: Political / Economic / Social influence = influence of that theme (a story has at most one); Campaign influence = elections only;
... A29: scandal, scandal_leader, unscandal, sweep; fa_n = how many.

Sheet Stories
A1: key | B1: name | C1: type | D1: theme | E1: cost | F1: Prestige | G1: Influence (plain) | H1: Political influence | I1: Economic influence | J1: Social influence | K1: Campaign influence | L1: draw | M1: trash | N1: gain_upto | O1: chain | P1: per_same | Q1: per_office | R1: attack | S1: defense | T1: retract | U1: ongoing_gen | V1: ongoing_draw | W1: others_bonus | X1: others_theme | Y1: released | Z1: year | AA1: copies | AB1: card_text | AC1: flavor
A2: letter | B2: Letter to the Editor | C2: Starter | E2: 0 | F2: 0 | G2: 1 | H2: 0 | I2: 0 | J2: 0 | K2: 0 | L2: 0 | M2: 0 | N2: 0 | O2: 0 | P2: 0 | Q2: 0 | S2: 0 | T2: 0 | U2: 0 | V2: 0 | W2: 0 | AA2: 7 | AB2: +1 influence. | AC2: A subscriber's opinion, printed at no charge.
A3: notice | B3: Local Notice | C3: Starter | E3: 0 | F3: 0 | G3: 0 | H3: 0 | I3: 0 | J3: 0 | K3: 0 | L3: 0 | M3: 0 | N3: 0 | O3: 0 | P3: 0 | Q3: 0 | S3: 0 | T3: 0 | U3: 0 | V3: 0 | W3: 0 | AA3: 3 | AB3: No effect. Destroy it when you can. | AC3: Strayed cattle, a church supper. Fills the column; moves no one.
A4: editorial | B4: Editorial | C4: Editorial | E4: 3 | F4: 1 | G4: 2 | H4: 0 | I4: 0 | J4: 0 | K4: 0 | L4: 0 | M4: 0 | N4: 0 | O4: 0 | P4: 0 | Q4: 0 | S4: 0 | T4: 0 | U4: 0 | V4: 0 | W4: 0 | AA4: 16 | AB4: +2 influence. | AC4: The editor's own voice, always on offer.
A5: scandal | B5: Scandal | C5: Scandal | E5: 0 | F5: -1 | G5: 0 | H5: 0 | I5: 0 | J5: 0 | K5: 0 | L5: 0 | M5: 0 | N5: 0 | O5: 0 | P5: 0 | Q5: 0 | S5: 0 | T5: 0 | U5: 0 | V5: 0 | W5: 0 | AA5: 20 | AB5: -1 prestige at the end of the game. | AC5: Something printed about you. It will not go away.
A6: stamp_act | B6: The Stamp Act | C6: Negative story | D6: Economic | E6: 3 | F6: 0 | G6: 1 | H6: 0 | I6: 1 | J6: 0 | K6: 0 | L6: 0 | M6: 0 | N6: 0 | O6: 0 | P6: 0 | Q6: 0 | R6: discard | S6: 0 | T6: 0 | U6: 0 | V6: 0 | W6: 0 | Y6: 1796 | Z6: 1765 | AA6: 1 | AB6: +1 influence, +1 Economic. Attack: each rival paper discards a card at random; +1 influence if it hits any of them. Worth no prestige. | AC6: A tax on every sheet a printer used. The printers led the resistance, and never forgot who had tried to tax the press.
A7: boston_massacre | B7: The Boston Massacre | C7: Negative story | D7: Social | E7: 4 | F7: 0 | G7: 1 | H7: 0 | I7: 0 | J7: 1 | K7: 0 | L7: 0 | M7: 0 | N7: 0 | O7: 0 | P7: 0 | Q7: 0 | R7: scandal | S7: 0 | T7: 0 | U7: 0 | V7: 0 | W7: 0 | Y7: 1796 | Z7: 1770 | AA7: 1 | AB7: +1 influence, +1 Social. Attack: each rival paper gains a Scandal; +1 influence if it hits any of them. Worth no prestige. | AC7: Five dead on King Street. Revere's engraving of it outsold anything true.
A8: tea_party | B8: The Boston Tea Party | C8: Economic story | D8: Economic | E8: 4 | F8: 1 | G8: 2 | H8: 0 | I8: 1 | J8: 0 | K8: 0 | L8: 0 | M8: 0 | N8: 0 | O8: 0 | P8: 1 | Q8: 0 | S8: 0 | T8: 0 | U8: 0 | V8: 0 | W8: 0 | Y8: 1796 | Z8: 1773 | AA8: 1 | AB8: +2 influence, +1 Economic. +1 influence for each other Economic story you play this turn. | AC8: Three shiploads of East India tea in the harbour, and a question about who governs a colony.
A9: common_sense | B9: Common Sense | C9: Social story | D9: Social | E9: 6 | F9: 2 | G9: 0 | H9: 0 | I9: 0 | J9: 2 | K9: 0 | L9: 1 | M9: 0 | N9: 0 | O9: 2 | P9: 0 | Q9: 0 | S9: 1 | T9: 0 | U9: 0 | V9: 0 | W9: 0 | Y9: 1796 | Z9: 1776 | AA9: 1 | AB9: +2 Social, draw 1 card. If you play another Social story this turn, +2 influence. Defense: discard this from your hand to ignore a negative story, and draw a card. | AC9: Paine's pamphlet ran through edition after edition in months. Kings, it turned out, were optional.
A10: declaration | B10: The Declaration of Independence | C10: Political story | D10: Political | E10: 5 | F10: 1 | G10: 2 | H10: 2 | I10: 0 | J10: 0 | K10: 2 | L10: 0 | M10: 0 | N10: 0 | O10: 0 | P10: 0 | Q10: 0 | S10: 0 | T10: 1 | U10: 0 | V10: 0 | W10: 0 | Y10: 1796 | Z10: 1776 | AA10: 1 | AB10: +2 influence, +2 Political, +2 Campaign (elections only). Retraction: draw a card, and you may destroy a Scandal in your hand or discard pile. | AC10: Printed overnight as a broadside and read aloud from courthouse steps. Everyone would claim it.
A11: saratoga | B11: Saratoga | C11: Political story | D11: Political | E11: 5 | F11: 1 | G11: 2 | H11: 2 | I11: 0 | J11: 0 | K11: 2 | L11: 0 | M11: 0 | N11: 0 | O11: 0 | P11: 0 | Q11: 0 | S11: 0 | T11: 1 | U11: 0 | V11: 0 | W11: 0 | Y11: 1796 | Z11: 1777 | AA11: 1 | AB11: +2 influence, +2 Political, +2 Campaign (elections only). Retraction: draw a card, and you may destroy a Scandal in your hand or discard pile. | AC11: Burgoyne surrendered an army, and France decided the rebellion was worth backing.
A12: valley_forge | B12: Valley Forge | C12: Social story | D12: Social | E12: 2 | F12: 1 | G12: 1 | H12: 0 | I12: 0 | J12: 0 | K12: 0 | L12: 1 | M12: 0 | N12: 0 | O12: 0 | P12: 0 | Q12: 0 | S12: 1 | T12: 0 | U12: 0 | V12: 0 | W12: 0 | Y12: 1796 | Z12: 1777 | AA12: 1 | AB12: +1 influence, draw 1 card. Defense: discard this from your hand to ignore a negative story, and draw a card. | AC12: A winter camp starved by a Congress that could ask the states for supplies but not require them.
A13: articles_confederation | B13: The Articles of Confederation | C13: Political story | D13: Political | E13: 2 | F13: 1 | G13: 1 | H13: 2 | I13: 0 | J13: 0 | K13: 0 | L13: 0 | M13: 0 | N13: 0 | O13: 0 | P13: 0 | Q13: 0 | S13: 0 | T13: 0 | U13: 0 | V13: 0 | W13: 0 | Y13: 1796 | Z13: 1781 | AA13: 1 | AB13: +1 influence, +2 Political. | AC13: A league of friendship among sovereign states, with no power to tax and no one to enforce it.
A14: newburgh | B14: The Newburgh Conspiracy | C14: Negative story | D14: Political | E14: 2 | F14: 0 | G14: 1 | H14: 0 | I14: 0 | J14: 0 | K14: 0 | L14: 0 | M14: 0 | N14: 0 | O14: 0 | P14: 0 | Q14: 0 | R14: discard | S14: 0 | T14: 0 | U14: 0 | V14: 0 | W14: 0 | Y14: 1796 | Z14: 1783 | AA14: 1 | AB14: +1 influence. Attack: each rival paper discards a card at random; +1 influence if it hits any of them. Worth no prestige. | AC14: Unpaid officers threatened Congress. Washington fumbled for his spectacles and talked them down.
A15: treaty_of_paris | B15: The Treaty of Paris | C15: Economic story | D15: Economic | E15: 6 | F15: 2 | G15: 2 | H15: 0 | I15: 2 | J15: 0 | K15: 0 | L15: 0 | M15: 0 | N15: 4 | O15: 0 | P15: 1 | Q15: 0 | S15: 0 | T15: 0 | U15: 0 | V15: 0 | W15: 0 | Y15: 1796 | Z15: 1783 | AA15: 1 | AB15: +2 influence, +2 Economic. Gain a story costing 4 or less from the exchange. +1 influence for each other Economic story you play this turn. | AC15: Independence, fisheries and the land to the Mississippi. Peace sells as well as war.
A16: pennsylvania_packet | B16: The First American Daily | C16: Media event | E16: 5 | F16: 1 | G16: 0 | H16: 0 | I16: 0 | J16: 0 | K16: 0 | L16: 0 | M16: 0 | N16: 0 | O16: 0 | P16: 0 | Q16: 0 | S16: 0 | T16: 0 | U16: 1 | V16: 0 | W16: 1 | X16: Economic | Y16: 1796 | Z16: 1784 | AA16: 1 | AB16: Stays in play for the rest of the game. Ongoing: at the start of each of your turns, +1 influence. Every other paper gets +1 Economic influence at the start of each of its turns. | AC16: The Pennsylvania Packet went daily. Advertisers discovered they could reach a city every morning.
A17: shays_rebellion | B17: Shays' Rebellion | C17: Negative story | D17: Economic | E17: 3 | F17: 0 | G17: 1 | H17: 0 | I17: 1 | J17: 0 | K17: 0 | L17: 0 | M17: 0 | N17: 0 | O17: 0 | P17: 0 | Q17: 0 | R17: discard | S17: 0 | T17: 0 | U17: 0 | V17: 0 | W17: 0 | Y17: 1796 | Z17: 1786 | AA17: 1 | AB17: +1 influence, +1 Economic. Attack: each rival paper discards a card at random; +1 influence if it hits any of them. Worth no prestige. | AC17: Farmers closed the courts in western Massachusetts, and the Confederation could do nothing about it.
A18: antifederalist_papers | B18: Brutus and the Federal Farmer | C18: Political story | D18: Political | E18: 3 | F18: 1 | G18: 1 | H18: 2 | I18: 0 | J18: 0 | K18: 1 | L18: 0 | M18: 0 | N18: 0 | O18: 0 | P18: 0 | Q18: 0 | S18: 0 | T18: 1 | U18: 0 | V18: 0 | W18: 0 | Y18: 1796 | Z18: 1787 | AA18: 1 | AB18: +1 influence, +2 Political, +1 Campaign (elections only). Retraction: draw a card, and you may destroy a Scandal in your hand or discard pile. | AC18: The case against ratification: a consolidated government would swallow the states and the liberties with them.
A19: constitutional_convention | B19: The Constitutional Convention | C19: Political story | D19: Political | E19: 3 | F19: 1 | G19: 1 | H19: 2 | I19: 0 | J19: 0 | K19: 1 | L19: 0 | M19: 0 | N19: 0 | O19: 0 | P19: 0 | Q19: 0 | S19: 0 | T19: 1 | U19: 0 | V19: 0 | W19: 0 | Y19: 1796 | Z19: 1787 | AA19: 1 | AB19: +1 influence, +2 Political, +1 Campaign (elections only). Retraction: draw a card, and you may destroy a Scandal in your hand or discard pile. | AC19: Delegates sent to amend the Articles locked the doors in Philadelphia and wrote a new government.
A20: federalist_papers | B20: The Federalist | C20: Political story | D20: Political | E20: 4 | F20: 1 | G20: 1 | H20: 2 | I20: 0 | J20: 0 | K20: 0 | L20: 0 | M20: 0 | N20: 0 | O20: 0 | P20: 0 | Q20: 1 | S20: 0 | T20: 1 | U20: 0 | V20: 0 | W20: 0 | Y20: 1796 | Z20: 1787 | AA20: 1 | AB20: +1 influence, +2 Political. +1 Political for each election you have won. Retraction: draw a card, and you may destroy a Scandal in your hand or discard pile. | AC20: Eighty-five essays by Publius in the New York papers, arguing for a government that could act.
A21: northwest_ordinance | B21: The Northwest Ordinance | C21: Economic story | D21: Economic | E21: 3 | F21: 1 | G21: 1 | H21: 0 | I21: 1 | J21: 0 | K21: 0 | L21: 0 | M21: 1 | N21: 0 | O21: 0 | P21: 1 | Q21: 0 | S21: 0 | T21: 0 | U21: 0 | V21: 0 | W21: 0 | Y21: 1796 | Z21: 1787 | AA21: 1 | AB21: +1 influence, +1 Economic. You may destroy a card in your hand or discard pile. +1 influence for each other Economic story you play this turn. | AC21: Congress would govern the western territories, and no slavery would cross the Ohio.
A22: gazette_of_the_us | B22: The Gazette of the United States | C22: Social story | D22: Social | E22: 4 | F22: 1 | G22: 0 | H22: 0 | I22: 0 | J22: 2 | K22: 0 | L22: 1 | M22: 0 | N22: 0 | O22: 1 | P22: 0 | Q22: 0 | S22: 0 | T22: 0 | U22: 0 | V22: 0 | W22: 0 | Y22: 1796 | Z22: 1789 | AA22: 1 | AB22: +2 Social, draw 1 card. If you play another Social story this turn, +1 influence. | AC22: Fenno's paper followed the government to New York and spoke for Hamilton's Treasury.
A23: judiciary_act | B23: The Judiciary Act | C23: Political story | D23: Political | E23: 2 | F23: 1 | G23: 1 | H23: 2 | I23: 0 | J23: 0 | K23: 0 | L23: 0 | M23: 0 | N23: 0 | O23: 0 | P23: 0 | Q23: 0 | S23: 0 | T23: 0 | U23: 0 | V23: 0 | W23: 0 | Y23: 1796 | Z23: 1789 | AA23: 1 | AB23: +1 influence, +2 Political. | AC23: A Supreme Court, circuit courts and district courts: the federal government acquired a reach.
A24: assumption | B24: The Assumption of State Debts | C24: Economic story | D24: Economic | E24: 4 | F24: 1 | G24: 2 | H24: 0 | I24: 1 | J24: 0 | K24: 0 | L24: 0 | M24: 0 | N24: 0 | O24: 0 | P24: 1 | Q24: 0 | S24: 0 | T24: 0 | U24: 0 | V24: 0 | W24: 0 | Y24: 1796 | Z24: 1790 | AA24: 1 | AB24: +2 influence, +1 Economic. +1 influence for each other Economic story you play this turn. | AC24: The nation took on the war debts of the states, and the speculators who held them grew rich.
A25: residence_act | B25: The Residence Act | C25: Economic story | D25: Economic | E25: 4 | F25: 1 | G25: 2 | H25: 0 | I25: 1 | J25: 0 | K25: 0 | L25: 0 | M25: 0 | N25: 0 | O25: 0 | P25: 1 | Q25: 0 | S25: 0 | T25: 0 | U25: 0 | V25: 0 | W25: 0 | Y25: 1796 | Z25: 1790 | AA25: 1 | AB25: +2 influence, +1 Economic. +1 influence for each other Economic story you play this turn. | AC25: The capital would go to the Potomac, the price the South extracted for assumption.
A26: bank_of_the_us | B26: The Bank of the United States | C26: Economic story | D26: Economic | E26: 5 | F26: 1 | G26: 2 | H26: 0 | I26: 1 | J26: 0 | K26: 0 | L26: 0 | M26: 1 | N26: 0 | O26: 0 | P26: 1 | Q26: 0 | S26: 0 | T26: 0 | U26: 0 | V26: 0 | W26: 0 | Y26: 1796 | Z26: 1791 | AA26: 1 | AB26: +2 influence, +1 Economic. You may destroy a card in your hand or discard pile. +1 influence for each other Economic story you play this turn. | AC26: Hamilton's bank, chartered under powers the Constitution never named. Jefferson called it unconstitutional.
A27: bill_of_rights | B27: The Bill of Rights | C27: Social story | D27: Social | E27: 2 | F27: 1 | G27: 1 | H27: 0 | I27: 0 | J27: 0 | K27: 0 | L27: 1 | M27: 0 | N27: 0 | O27: 0 | P27: 0 | Q27: 0 | S27: 1 | T27: 0 | U27: 0 | V27: 0 | W27: 0 | Y27: 1796 | Z27: 1791 | AA27: 1 | AB27: +1 influence, draw 1 card. Defense: discard this from your hand to ignore a negative story, and draw a card. | AC27: Ten amendments, the first of which said Congress shall make no law abridging the freedom of the press.
A28: national_gazette | B28: The National Gazette | C28: Social story | D28: Social | E28: 4 | F28: 1 | G28: 0 | H28: 0 | I28: 0 | J28: 2 | K28: 0 | L28: 1 | M28: 0 | N28: 0 | O28: 1 | P28: 0 | Q28: 0 | S28: 0 | T28: 0 | U28: 0 | V28: 0 | W28: 0 | Y28: 1796 | Z28: 1791 | AA28: 1 | AB28: +2 Social, draw 1 card. If you play another Social story this turn, +1 influence. | AC28: Freneau's opposition paper, subsidised by a clerkship in Jefferson's own State Department.
A29: report_manufactures | B29: The Report on Manufactures | C29: Economic story | D29: Economic | E29: 4 | F29: 1 | G29: 2 | H29: 0 | I29: 1 | J29: 0 | K29: 0 | L29: 0 | M29: 0 | N29: 0 | O29: 0 | P29: 1 | Q29: 0 | S29: 0 | T29: 0 | U29: 0 | V29: 0 | W29: 0 | Y29: 1796 | Z29: 1791 | AA29: 1 | AB29: +2 influence, +1 Economic. +1 influence for each other Economic story you play this turn. | AC29: Hamilton on why a farming republic should build factories it does not yet want.
A30: rights_of_man | B30: The Rights of Man | C30: Social story | D30: Social | E30: 4 | F30: 1 | G30: 0 | H30: 0 | I30: 0 | J30: 2 | K30: 0 | L30: 1 | M30: 0 | N30: 0 | O30: 1 | P30: 0 | Q30: 0 | S30: 0 | T30: 0 | U30: 0 | V30: 0 | W30: 0 | Y30: 1796 | Z30: 1791 | AA30: 1 | AB30: +2 Social, draw 1 card. If you play another Social story this turn, +1 influence. | AC30: Paine's defence of the French Revolution, printed in America with a note from the Secretary of State.
A31: postal_act_1792 | B31: The Postal Act of 1792 | C31: Media event | E31: 6 | F31: 2 | G31: 0 | H31: 0 | I31: 0 | J31: 0 | K31: 0 | L31: 0 | M31: 0 | N31: 0 | O31: 0 | P31: 0 | Q31: 0 | S31: 0 | T31: 0 | U31: 0 | V31: 1 | W31: 1 | X31: Political | Y31: 1796 | Z31: 1792 | AA31: 1 | AB31: Stays in play for the rest of the game. Ongoing: at the start of each of your turns, draw 1 card. Every other paper gets +1 Political influence at the start of each of its turns. | AC31: Newspapers carried anywhere in the Union for a cent or a cent and a half, and printers swapped papers postage-free. A national press became a business.
A32: citizen_genet | B32: Citizen Genet | C32: Negative story | D32: Social | E32: 3 | F32: 0 | G32: 1 | H32: 0 | I32: 0 | J32: 1 | K32: 0 | L32: 0 | M32: 0 | N32: 0 | O32: 0 | P32: 0 | Q32: 0 | R32: discard | S32: 0 | T32: 0 | U32: 0 | V32: 0 | W32: 0 | Y32: 1796 | Z32: 1793 | AA32: 1 | AB32: +1 influence, +1 Social. Attack: each rival paper discards a card at random; +1 influence if it hits any of them. Worth no prestige. | AC32: The French minister appealed to the people over Washington's head, and embarrassed his friends.
A33: democratic_societies | B33: The Democratic-Republican Societies | C33: Social story | D33: Social | E33: 3 | F33: 1 | G33: 0 | H33: 0 | I33: 0 | J33: 1 | K33: 0 | L33: 1 | M33: 0 | N33: 0 | O33: 1 | P33: 0 | Q33: 0 | S33: 1 | T33: 0 | U33: 0 | V33: 0 | W33: 0 | Y33: 1796 | Z33: 1794 | AA33: 1 | AB33: +1 Social, draw 1 card. If you play another Social story this turn, +1 influence. Defense: discard this from your hand to ignore a negative story, and draw a card. | AC33: Clubs of mechanics and farmers toasting France. Washington blamed them for the rebellion in the west.
A34: whiskey_rebellion | B34: The Whiskey Rebellion | C34: Negative story | D34: Economic | E34: 3 | F34: 0 | G34: 1 | H34: 0 | I34: 1 | J34: 0 | K34: 0 | L34: 0 | M34: 0 | N34: 0 | O34: 0 | P34: 0 | Q34: 0 | R34: discard | S34: 0 | T34: 0 | U34: 0 | V34: 0 | W34: 0 | Y34: 1796 | Z34: 1794 | AA34: 1 | AB34: +1 influence, +1 Economic. Attack: each rival paper discards a card at random; +1 influence if it hits any of them. Worth no prestige. | AC34: Thirteen thousand militia marched on western Pennsylvania to collect a tax on whiskey.
A35: jay_treaty | B35: The Jay Treaty | C35: Political story | D35: Political | E35: 4 | F35: 1 | G35: 1 | H35: 2 | I35: 0 | J35: 0 | K35: 0 | L35: 0 | M35: 0 | N35: 0 | O35: 0 | P35: 0 | Q35: 1 | S35: 0 | T35: 1 | U35: 0 | V35: 0 | W35: 0 | Y35: 1796 | Z35: 1795 | AA35: 1 | AB35: +1 influence, +2 Political. +1 Political for each election you have won. Retraction: draw a card, and you may destroy a Scandal in your hand or discard pile. | AC35: Peace with Britain, bought with the carrying trade. Burned in effigy from Boston to Charleston.
A36: alien_sedition | B36: The Alien and Sedition Acts | C36: Negative story | D36: Social | E36: 2 | F36: 0 | G36: 1 | H36: 0 | I36: 0 | J36: 0 | K36: 0 | L36: 0 | M36: 0 | N36: 0 | O36: 0 | P36: 0 | Q36: 0 | R36: discard | S36: 0 | T36: 0 | U36: 0 | V36: 0 | W36: 0 | Y36: 1800 | Z36: 1798 | AA36: 1 | AB36: +1 influence. Attack: each rival paper discards a card at random; +1 influence if it hits any of them. Worth no prestige. | AC36: Twenty-five arrests, and most of them printers. The press learned what it was worth.
A37: kentucky_resolutions | B37: The Kentucky and Virginia Resolutions | C37: Political story | D37: Political | E37: 2 | F37: 1 | G37: 1 | H37: 2 | I37: 0 | J37: 0 | K37: 0 | L37: 0 | M37: 0 | N37: 0 | O37: 0 | P37: 0 | Q37: 0 | S37: 0 | T37: 0 | U37: 0 | V37: 0 | W37: 0 | Y37: 1800 | Z37: 1798 | AA37: 1 | AB37: +1 influence, +2 Political. | AC37: Jefferson and Madison, anonymously, arguing that a state might judge the compact for itself.
A38: xyz_affair | B38: The XYZ Affair | C38: Negative story | D38: Social | E38: 4 | F38: 0 | G38: 1 | H38: 0 | I38: 0 | J38: 1 | K38: 0 | L38: 0 | M38: 0 | N38: 0 | O38: 0 | P38: 0 | Q38: 0 | R38: scandal | S38: 0 | T38: 0 | U38: 0 | V38: 0 | W38: 0 | Y38: 1800 | Z38: 1798 | AA38: 1 | AB38: +1 influence, +1 Social. Attack: each rival paper gains a Scandal; +1 influence if it hits any of them. Worth no prestige. | AC38: Millions for defence, not one cent for tribute. The best copy the Federalists ever had.
A39: marbury | B39: Marbury v. Madison | C39: Political story | D39: Political | E39: 2 | F39: 1 | G39: 1 | H39: 2 | I39: 0 | J39: 0 | K39: 0 | L39: 0 | M39: 0 | N39: 0 | O39: 0 | P39: 0 | Q39: 0 | S39: 0 | T39: 0 | U39: 0 | V39: 0 | W39: 0 | Y39: 1804 | Z39: 1803 | AA39: 1 | AB39: +1 influence, +2 Political. | AC39: Marshall gave up a commission and took the power to void an act of Congress.
A40: louisiana_purchase | B40: The Louisiana Purchase | C40: Economic story | D40: Economic | E40: 6 | F40: 2 | G40: 2 | H40: 0 | I40: 2 | J40: 0 | K40: 0 | L40: 0 | M40: 0 | N40: 4 | O40: 0 | P40: 1 | Q40: 0 | S40: 0 | T40: 0 | U40: 0 | V40: 0 | W40: 0 | Y40: 1804 | Z40: 1803 | AA40: 1 | AB40: +2 influence, +2 Economic. Gain a story costing 4 or less from the exchange. +1 influence for each other Economic story you play this turn. | AC40: Fifteen million dollars, and a strict constructionist who could not find the clause.
...

Sheet Elections
A1: space | B1: year | C1: era | D1: card_name | E1: Prestige | F1: Prestige per office | G1: Influence (plain) | H1: Candidate-theme influence | I1: nation | J1: nation_theme | K1: nation_threshold | L1: states | M1: states_theme | N1: states_threshold | O1: historical_winner | P1: p_draw | Q1: p_trash | R1: p_trash_draw | S1: p_gain_upto | T1: p_recover | U1: p_per_kind | V1: p_scry | W1: p_stay_gen | X1: p_attack | Y1: power_text | Z1: fa_kind | AA1: fa_n | AB1: fa_name | AC1: fa_text | AD1: card_text
A2: 1 | B2: 1796 | C2: I | D2: The Farewell Address | E2: 3 | F2: 0 | G2: 2 | H2: 2 | I2: John Adams | J2: Political | K2: 8 | L2: Thomas Jefferson | M2: Social | N2: 10 | O2: nation | P2: 1 | Q2: 0 | R2: 0 | S2: 0 | T2: 0 | U2: 0 | V2: 0 | W2: 0 | Y2: +2 influence, draw a card. | AA2: 0 | AD2: +2 influence, draw a card. Also +2 of the elected candidate's theme. Worth 3 prestige.
A3: 2 | B3: 1800 | C3: I | D3: The Revolution of 1800 | E3: 3 | F3: 0 | G3: 2 | H3: 2 | I3: John Adams | J3: Social | K3: 10 | L3: Thomas Jefferson | M3: Political | N3: 8 | O3: states | P3: 2 | Q3: 1 | R3: 0 | S3: 0 | T3: 0 | U3: 0 | V3: 0 | W3: 0 | Y3: +2 influence, draw 2 cards, then you may destroy a card in your hand or discard pile. | Z3: discard_leader | AA3: 1 | AB3: The Sedition Act | AC3: The paper (or papers) holding the most offices discards a card at random. | AD3: +2 influence, draw 2 cards, then you may destroy a card in your hand or discard pile. Also +2 of the elected candidate's theme. Worth 3 prestige.
A4: 3 | B4: 1804 | C4: I | D4: The Louisiana Purchase | E4: 3 | F4: 0 | G4: 2 | H4: 2 | I4: Thomas Jefferson | J4: Political | K4: 9 | L4: Charles C. Pinckney | M4: Economic | N4: 11 | O4: nation | P4: 0 | Q4: 0 | R4: 0 | S4: 4 | T4: 0 | U4: 0 | V4: 0 | W4: 0 | Y4: +2 influence. Gain a story costing 4 or less from the exchange. | Z4: draw | AA4: 1 | AB4: The Twelfth Amendment | AC4: Each paper draws a card. | AD4: +2 influence. Gain a story costing 4 or less from the exchange. Also +2 of the elected candidate's theme. Worth 3 prestige.
A5: 4 | B5: 1808 | C5: I | D5: The Embargo | E5: 3 | F5: 0 | G5: 4 | H5: 2 | I5: James Madison | J5: Political | K5: 9 | L5: Charles C. Pinckney | M5: Economic | N5: 11 | O5: nation | P5: 0 | Q5: 0 | R5: 0 | S5: 0 | T5: 0 | U5: 0 | V5: 0 | W5: 0 | Y5: +4 influence. | Z5: discard_dearest | AA5: 1 | AB5: The Embargo | AC5: Each paper discards the most expensive card in its hand. | AD5: +4 influence. Also +2 of the elected candidate's theme. Worth 3 prestige.
A6: 5 | B6: 1812 | C6: I | D6: Mr. Madison's War | E6: 4 | F6: 0 | G6: 0 | H6: 2 | I6: James Madison | J6: Social | K6: 10 | L6: DeWitt Clinton | M6: Political | N6: 12 | O6: nation | P6: 0 | Q6: 0 | R6: 0 | S6: 0 | T6: 0 | U6: 1 | V6: 0 | W6: 0 | Y6: +1 influence for each different kind of card you play this turn. | Z6: scandal_leader | AA6: 1 | AB6: Impressment | AC6: The paper (or papers) with the most prestige gains a Scandal. | AD6: +1 influence for each different kind of card you play this turn. Also +2 of the elected candidate's theme. Worth 4 prestige.
A7: 6 | B7: 1816 | C7: I | D7: Good Feelings | E7: 4 | F7: 0 | G7: 0 | H7: 2 | I7: James Monroe | J7: Economic | K7: 10 | L7: Rufus King | M7: Social | N7: 12 | O7: nation | P7: 3 | Q7: 0 | R7: 0 | S7: 0 | T7: 0 | U7: 0 | V7: 0 | W7: 0 | Y7: Draw 3 cards. | Z7: unscandal | AA7: 1 | AB7: Good Feelings | AC7: Each paper destroys a Scandal in its hand or discard pile. | AD7: Draw 3 cards. Also +2 of the elected candidate's theme. Worth 4 prestige.
A8: 7 | B8: 1820 | C8: II | D8: The Missouri Compromise | E8: 4 | F8: 0 | G8: 0 | H8: 3 | I8: John Quincy Adams | J8: Social | K8: 13 | L8: James Monroe | M8: Political | N8: 11 | O8: states | P8: 0 | Q8: 2 | R8: 1 | S8: 0 | T8: 0 | U8: 0 | V8: 0 | W8: 0 | Y8: Destroy up to 2 cards in your hand or discard pile; draw a card for each. | Z8: discard_leader | AA8: 1 | AB8: A Fire Bell in the Night | AC8: The paper (or papers) holding the most offices discards a card at random. | AD8: Destroy up to 2 cards in your hand or discard pile; draw a card for each. Also +3 of the elected candidate's theme. Worth 4 prestige.
A9: 8 | B9: 1824 | C9: II | D9: The Corrupt Bargain | E9: 4 | F9: 0 | G9: 0 | H9: 3 | I9: John Quincy Adams | J9: Social | K9: 11 | L9: Andrew Jackson | M9: Political | N9: 13 | O9: nation | P9: 0 | Q9: 0 | R9: 0 | S9: 0 | T9: 2 | U9: 0 | V9: 0 | W9: 0 | Y9: Put up to 2 cards from your discard pile into your hand. | Z9: scandal_leader | AA9: 1 | AB9: The Corrupt Bargain | AC9: The paper (or papers) with the most prestige gains a Scandal. | AD9: Put up to 2 cards from your discard pile into your hand. Also +3 of the elected candidate's theme. Worth 4 prestige.
A10: 9 | B10: 1828 | C10: II | D10: The Tariff of Abominations | E10: 5 | F10: 0 | G10: 3 | H10: 3 | I10: John Quincy Adams | J10: Economic | K10: 14 | L10: Andrew Jackson | M10: Social | N10: 12 | O10: states | P10: 1 | Q10: 0 | R10: 0 | S10: 0 | T10: 0 | U10: 0 | V10: 0 | W10: 0 | Y10: +3 influence, draw a card. | Z10: scandal_leader | AA10: 1 | AB10: Mudslinging | AC10: The paper (or papers) with the most prestige gains a Scandal. | AD10: +3 influence, draw a card. Also +3 of the elected candidate's theme. Worth 5 prestige.
A11: 10 | B11: 1832 | C11: II | D11: The Bank War | E11: 5 | F11: 0 | G11: 0 | H11: 3 | I11: Henry Clay | J11: Economic | K11: 14 | L11: Andrew Jackson | M11: Social | N11: 12 | O11: states | P11: 1 | Q11: 0 | R11: 0 | S11: 6 | T11: 0 | U11: 0 | V11: 0 | W11: 0 | Y11: Gain a story costing 6 or less from the exchange. Draw a card. | Z11: sweep | AA11: 1 | AB11: The Veto | AC11: The exchange is swept and dealt afresh. | AD11: Gain a story costing 6 or less from the exchange. Draw a card. Also +3 of the elected candidate's theme. Worth 5 prestige.
A12: 11 | B12: 1836 | C12: II | D12: The Specie Circular | E12: 5 | F12: 0 | G12: 3 | H12: 3 | I12: William Henry Harrison | J12: Political | K12: 15 | L12: Martin Van Buren | M12: Economic | N12: 13 | O12: states | P12: 2 | Q12: 0 | R12: 0 | S12: 0 | T12: 0 | U12: 0 | V12: 0 | W12: 0 | Y12: +3 influence, draw 2 cards. | Z12: discard_leader | AA12: 2 | AB12: The Panic of 1837 | AC12: The paper (or papers) holding the most offices discards 2 cards at random. | AD12: +3 influence, draw 2 cards. Also +3 of the elected candidate's theme. Worth 5 prestige.
A13: 12 | B13: 1840 | C13: II | D13: Log Cabin and Hard Cider | E13: 5 | F13: 0 | G13: 4 | H13: 3 | I13: William Henry Harrison | J13: Social | K13: 13 | L13: Martin Van Buren | M13: Economic | N13: 15 | O13: nation | P13: 0 | Q13: 0 | R13: 0 | S13: 0 | T13: 0 | U13: 0 | V13: 0 | W13: 0 | Y13: +4 influence. | Z13: draw | AA13: 1 | AB13: Tippecanoe and Tyler Too | AC13: Each paper draws a card. | AD13: +4 influence. Also +3 of the elected candidate's theme. Worth 5 prestige.
A14: 13 | B14: 1844 | C14: III | D14: Manifest Destiny | E14: 6 | F14: 0 | G14: 2 | H14: 4 | I14: Henry Clay | J14: Economic | K14: 16 | L14: James K. Polk | M14: Social | N14: 14 | O14: states | P14: 0 | Q14: 0 | R14: 0 | S14: 0 | T14: 0 | U14: 0 | V14: 3 | W14: 0 | Y14: +2 influence. Look at the top 3 stories of the main deck; put one into your hand, the rest on the bottom. | Z14: draw_fewest | AA14: 2 | AB14: Fifty-four Forty | AC14: The paper (or papers) with the fewest offices draws 2 cards. | AD14: +2 influence. Look at the top 3 stories of the main deck; put one into your hand, the rest on the bottom. Also +4 of the elected candidate's theme. Worth 6 prestige.
... A16: 15 | B16: 1852 | C16: III | D16: The Compromise of 1850 | E16: 6 | F16: 0 | G16: 0 | H16: 4 | I16: Winfield Scott | J16: Political | K16: 17 | L16: Franklin Pierce | M16: Economic | N16: 15 | O16: states | P16: 0 | Q16: 3 | R16: 1 | S16: 0 | T16: 0 | U16: 0 | V16: 0 | W16: 0 | Y16: Destroy up to 3 cards in your hand or discard pile; draw a card for each. | Z16: scandal_leader | AA16: 1 | AB16: The Fugitive Slave Act | AC16: The paper (or papers) with the most prestige gains a Scandal. | AD16: Destroy up to 3 cards in your hand or discard pile; draw a card for each. Also +4 of the elected candidate's theme. Worth 6 prestige.
A17: 16 | B17: 1856 | C17: III | D17: Bleeding Kansas | E17: 6 | F17: 0 | G17: 5 | H17: 4 | I17: John C. Fremont | J17: Economic | K17: 17 | L17: James Buchanan | M17: Political | N17: 15 | O17: states | P17: 0 | Q17: 0 | R17: 0 | S17: 0 | T17: 0 | U17: 0 | V17: 0 | W17: 0 | X17: scandal | Y17: +5 influence. Attack: each rival paper gains a Scandal. | Z17: discard_leader | AA17: 2 | AB17: Bleeding Kansas | AC17: The paper (or papers) holding the most offices discards 2 cards at random. | AD17: +5 influence. Attack: each rival paper gains a Scandal. Also +4 of the elected candidate's theme. Worth 6 prestige.
A18: 17 | B18: 1860 | C18: III | D18: Secession Winter | E18: 0 | F18: 1 | G18: 0 | H18: 4 | I18: Abraham Lincoln | J18: Political | K18: 16 | L18: Stephen A. Douglas | M18: Economic | N18: 18 | O18: nation | P18: 0 | Q18: 0 | R18: 0 | S18: 0 | T18: 0 | U18: 0 | V18: 0 | W18: 0 | Y18: The last election: the game ends after this turn. Worth 1 prestige for each election card you hold, this one included. | Z18: destroy_cheapest | AA18: 1 | AB18: Secession | AC18: Each paper destroys the cheapest card in its hand. | AD18: The last election: the game ends after this turn. Worth 1 prestige for each election card you hold, this one included.

Sheet Newspapers
A1: key | B1: name | C1: dc_super_hero | D1: leans | E1: ability | F1: flavor
A2: globe | B2: The Washington Globe | C2: Hawkman | D2: Political | E2: Your Political influence counts toward any candidate. | F2: Francis Blair's Globe, the party organ of the Jackson men: the line came from the White House.
A3: argus | B3: The Albany Argus | C3: Red Tornado | D3: Political | E3: Each election you win is worth +1 prestige at the end of the game. | F3: The voice of the Albany Regency, Van Buren's machine. It could elect anyone the party named.
A4: intelligencer | B4: The National Intelligencer | C4: Booster Gold | D4: Political | E4: You never gain Scandals: when a negative story would give you one, ignore it. | F4: Gales and Seaton's paper of record, printing the debates of Congress. Too dull to smear.
A5: journal | B5: The Journal of Commerce | C5: Nightwing | D5: Economic | E5: Your first and second Economic stories each turn give +1 influence each. | F5: Prices current, ship arrivals and the money market, for the merchants of New York.
A6: herald | B6: The New York Herald | C6: Shazam! | D6: Economic | E6: Once each turn, you may pay 2 influence to set aside the top story of the main deck; it joins your next hand. | F6: James Gordon Bennett's Herald: first with the news, by any means, at any cost.
A7: sun | B7: The Sun | C7: Batgirl | D7: Social | E7: Once each turn, you may discard a Scandal from your hand to draw three cards. | F7: Benjamin Day's Sun, a penny a copy: police court, murders, and the moon men.
A8: north_star | B8: The North Star | C8: Starfire | D8: Social | E8: Once each turn, if you play two or more Social stories, draw a card. | F8: Frederick Douglass's weekly from Rochester: "Right is of no sex - Truth is of no color."
A9: aurora | B9: The Aurora | C9: Black Canary | D9: Negative | E9: +1 influence for each different negative story you play. | F9: Benjamin Franklin Bache's Aurora, which called Washington a tyrant and Adams worse.

Sheet Summary
A1: Summary of the Stories sheet (formulas: edit the Stories sheet and these update)
A3: Card type | B3: Kinds | C3: Copies | D3: Total prestige (vp x copies)
A4: Political story | B4: =COUNTIFS(Stories!$C$2:$C$111,$A4) | C4: =SUMIFS(Stories!$AA$2:$AA$111,Stories!$C$2:$C$111,$A4) | D4: =SUMPRODUCT((Stories!$C$2:$C$111=$A4)*Stories!$F$2:$F$111*Stories!$AA$2:$AA$111)
A5: Economic story | B5: =COUNTIFS(Stories!$C$2:$C$111,$A5) | C5: =SUMIFS(Stories!$AA$2:$AA$111,Stories!$C$2:$C$111,$A5) | D5: =SUMPRODUCT((Stories!$C$2:$C$111=$A5)*Stories!$F$2:$F$111*Stories!$AA$2:$AA$111)
A6: Social story | B6: =COUNTIFS(Stories!$C$2:$C$111,$A6) | C6: =SUMIFS(Stories!$AA$2:$AA$111,Stories!$C$2:$C$111,$A6) | D6: =SUMPRODUCT((Stories!$C$2:$C$111=$A6)*Stories!$F$2:$F$111*Stories!$AA$2:$AA$111)
A7: Negative story | B7: =COUNTIFS(Stories!$C$2:$C$111,$A7) | C7: =SUMIFS(Stories!$AA$2:$AA$111,Stories!$C$2:$C$111,$A7) | D7: =SUMPRODUCT((Stories!$C$2:$C$111=$A7)*Stories!$F$2:$F$111*Stories!$AA$2:$AA$111)
A8: Media event | B8: =COUNTIFS(Stories!$C$2:$C$111,$A8) | C8: =SUMIFS(Stories!$AA$2:$AA$111,Stories!$C$2:$C$111,$A8) | D8: =SUMPRODUCT((Stories!$C$2:$C$111=$A8)*Stories!$F$2:$F$111*Stories!$AA$2:$AA$111)
A9: Starter | B9: =COUNTIFS(Stories!$C$2:$C$111,$A9) | C9: =SUMIFS(Stories!$AA$2:$AA$111,Stories!$C$2:$C$111,$A9) | D9: =SUMPRODUCT((Stories!$C$2:$C$111=$A9)*Stories!$F$2:$F$111*Stories!$AA$2:$AA$111)
A10: Editorial | B10: =COUNTIFS(Stories!$C$2:$C$111,$A10) | C10: =SUMIFS(Stories!$AA$2:$AA$111,Stories!$C$2:$C$111,$A10) | D10: =SUMPRODUCT((Stories!$C$2:$C$111=$A10)*Stories!$F$2:$F$111*Stories!$AA$2:$AA$111)
A11: Scandal | B11: =COUNTIFS(Stories!$C$2:$C$111,$A11) | C11: =SUMIFS(Stories!$AA$2:$AA$111,Stories!$C$2:$C$111,$A11) | D11: =SUMPRODUCT((Stories!$C$2:$C$111=$A11)*Stories!$F$2:$F$111*Stories!$AA$2:$AA$111)
A12: Total | B12: =SUM(B4:B11) | C12: =SUM(C4:C11) | D12: =SUM(D4:D11)
A14: Theme (stories and negative stories) | B14: Era I | C14: Era II | D14: Era III | E14: All
A15: Political | B15: =COUNTIFS(Stories!$D$2:$D$111,$A15,Stories!$Y$2:$Y$111,">=1796",Stories!$Y$2:$Y$111,"<=1804") | C15: =COUNTIFS(Stories!$D$2:$D$111,$A15,Stories!$Y$2:$Y$111,">=1808",Stories!$Y$2:$Y$111,"<=1828") | D15: =COUNTIFS(Stories!$D$2:$D$111,$A15,Stories!$Y$2:$Y$111,">=1832",Stories!$Y$2:$Y$111,"<=1860") | E15: =SUM(B15:D15)
A16: Economic | B16: =COUNTIFS(Stories!$D$2:$D$111,$A16,Stories!$Y$2:$Y$111,">=1796",Stories!$Y$2:$Y$111,"<=1804") | C16: =COUNTIFS(Stories!$D$2:$D$111,$A16,Stories!$Y$2:$Y$111,">=1808",Stories!$Y$2:$Y$111,"<=1828") | D16: =COUNTIFS(Stories!$D$2:$D$111,$A16,Stories!$Y$2:$Y$111,">=1832",Stories!$Y$2:$Y$111,"<=1860") | E16: =SUM(B16:D16)
A17: Social | B17: =COUNTIFS(Stories!$D$2:$D$111,$A17,Stories!$Y$2:$Y$111,">=1796",Stories!$Y$2:$Y$111,"<=1804") | C17: =COUNTIFS(Stories!$D$2:$D$111,$A17,Stories!$Y$2:$Y$111,">=1808",Stories!$Y$2:$Y$111,"<=1828") | D17: =COUNTIFS(Stories!$D$2:$D$111,$A17,Stories!$Y$2:$Y$111,">=1832",Stories!$Y$2:$Y$111,"<=1860") | E17: =SUM(B17:D17)
A19: Elections: fixed prestige on the 17 cards (1860 is worth 1 per office held, not counted) | B19: =SUM(Elections!$E$2:$E$18)
